2025-05-23 21:58:10,666 - pygad.pygad - ERROR - 
All the 3 fits failed.
It is very likely that your model is misconfigured.
You can try to debug the error by setting error_score='raise'.

Below are more details about the failures:
--------------------------------------------------------------------------------
3 fits failed with the following error:
Traceback (most recent call last):
  File "c:\python\.venv\Lib\site-packages\pandas\core\indexes\base.py", line 3805, in get_loc
    return self._engine.get_loc(casted_key)
           ~~~~~~~~~~~~~~~~~~~~^^^^^^^^^^^^
  File "index.pyx", line 167, in pandas._libs.index.IndexEngine.get_loc
  File "index.pyx", line 196, in pandas._libs.index.IndexEngine.get_loc
  File "pandas\\_libs\\hashtable_class_helper.pxi", line 7081, in pandas._libs.hashtable.PyObjectHashTable.get_item
  File "pandas\\_libs\\hashtable_class_helper.pxi", line 7089, in pandas._libs.hashtable.PyObjectHashTable.get_item
KeyError: 'Объект 1 Угол'

The above exception was the direct cause of the following exception:

Traceback (most recent call last):
  File "c:\python\.venv\Lib\site-packages\sklearn\utils\_indexing.py", line 364, in _get_column_indices
    col_idx = all_columns.get_loc(col)
  File "c:\python\.venv\Lib\site-packages\pandas\core\indexes\base.py", line 3812, in get_loc
    raise KeyError(key) from err
KeyError: 'Объект 1 Угол'

The above exception was the direct cause of the following exception:

Traceback (most recent call last):
  File "c:\python\.venv\Lib\site-packages\sklearn\model_selection\_validation.py", line 866, in _fit_and_score
    estimator.fit(X_train, y_train, **fit_params)
    ~~~~~~~~~~~~~^^^^^^^^^^^^^^^^^^^^^^^^^^^^^^^^
  File "c:\python\.venv\Lib\site-packages\sklearn\base.py", line 1389, in wrapper
    return fit_method(estimator, *args, **kwargs)
  File "c:\python\.venv\Lib\site-packages\sklearn\pipeline.py", line 654, in fit
    Xt = self._fit(X, y, routed_params, raw_params=params)
  File "c:\python\.venv\Lib\site-packages\sklearn\pipeline.py", line 588, in _fit
    X, fitted_transformer = fit_transform_one_cached(
                            ~~~~~~~~~~~~~~~~~~~~~~~~^
        cloned_transformer,
        ^^^^^^^^^^^^^^^^^^^
    ...<5 lines>...
        params=step_params,
        ^^^^^^^^^^^^^^^^^^^
    )
    ^
  File "c:\python\.venv\Lib\site-packages\joblib\memory.py", line 312, in __call__
    return self.func(*args, **kwargs)
           ~~~~~~~~~^^^^^^^^^^^^^^^^^
  File "c:\python\.venv\Lib\site-packages\sklearn\pipeline.py", line 1551, in _fit_transform_one
    res = transformer.fit_transform(X, y, **params.get("fit_transform", {}))
  File "c:\python\.venv\Lib\site-packages\sklearn\utils\_set_output.py", line 319, in wrapped
    data_to_wrap = f(self, X, *args, **kwargs)
  File "c:\python\.venv\Lib\site-packages\sklearn\base.py", line 1389, in wrapper
    return fit_method(estimator, *args, **kwargs)
  File "c:\python\.venv\Lib\site-packages\sklearn\compose\_column_transformer.py", line 993, in fit_transform
    self._validate_column_callables(X)
    ~~~~~~~~~~~~~~~~~~~~~~~~~~~~~~~^^^
  File "c:\python\.venv\Lib\site-packages\sklearn\compose\_column_transformer.py", line 552, in _validate_column_callables
    transformer_to_input_indices[name] = _get_column_indices(X, columns)
                                         ~~~~~~~~~~~~~~~~~~~^^^^^^^^^^^^
  File "c:\python\.venv\Lib\site-packages\sklearn\utils\_indexing.py", line 372, in _get_column_indices
    raise ValueError("A given column is not a column of the dataframe") from e
ValueError: A given column is not a column of the dataframe
Traceback (most recent call last):
  File "c:\python\.venv\Lib\site-packages\pygad\pygad.py", line 1697, in cal_pop_fitness
    fitness = self.fitness_func(self, sol, sol_idx)
  File "C:\Users\IronSmail\AppData\Local\Temp\ipykernel_6008\3357027851.py", line 30, in fitness_rf
    return evaluate(model, X, y)
  File "C:\Users\IronSmail\AppData\Local\Temp\ipykernel_6008\3357027851.py", line 21, in evaluate
    return cross_val_score(pipeline, X, y, cv=3, scoring='accuracy').mean()
           ~~~~~~~~~~~~~~~^^^^^^^^^^^^^^^^^^^^^^^^^^^^^^^^^^^^^^^^^^
  File "c:\python\.venv\Lib\site-packages\sklearn\utils\_param_validation.py", line 216, in wrapper
    return func(*args, **kwargs)
  File "c:\python\.venv\Lib\site-packages\sklearn\model_selection\_validation.py", line 684, in cross_val_score
    cv_results = cross_validate(
        estimator=estimator,
    ...<9 lines>...
        error_score=error_score,
    )
  File "c:\python\.venv\Lib\site-packages\sklearn\utils\_param_validation.py", line 216, in wrapper
    return func(*args, **kwargs)
  File "c:\python\.venv\Lib\site-packages\sklearn\model_selection\_validation.py", line 431, in cross_validate
    _warn_or_raise_about_fit_failures(results, error_score)
    ~~~~~~~~~~~~~~~~~~~~~~~~~~~~~~~~~^^^^^^^^^^^^^^^^^^^^^^
  File "c:\python\.venv\Lib\site-packages\sklearn\model_selection\_validation.py", line 517, in _warn_or_raise_about_fit_failures
    raise ValueError(all_fits_failed_message)
ValueError: 
All the 3 fits failed.
It is very likely that your model is misconfigured.
You can try to debug the error by setting error_score='raise'.

Below are more details about the failures:
--------------------------------------------------------------------------------
3 fits failed with the following error:
Traceback (most recent call last):
  File "c:\python\.venv\Lib\site-packages\pandas\core\indexes\base.py", line 3805, in get_loc
    return self._engine.get_loc(casted_key)
           ~~~~~~~~~~~~~~~~~~~~^^^^^^^^^^^^
  File "index.pyx", line 167, in pandas._libs.index.IndexEngine.get_loc
  File "index.pyx", line 196, in pandas._libs.index.IndexEngine.get_loc
  File "pandas\\_libs\\hashtable_class_helper.pxi", line 7081, in pandas._libs.hashtable.PyObjectHashTable.get_item
  File "pandas\\_libs\\hashtable_class_helper.pxi", line 7089, in pandas._libs.hashtable.PyObjectHashTable.get_item
KeyError: 'Объект 1 Угол'

The above exception was the direct cause of the following exception:

Traceback (most recent call last):
  File "c:\python\.venv\Lib\site-packages\sklearn\utils\_indexing.py", line 364, in _get_column_indices
    col_idx = all_columns.get_loc(col)
  File "c:\python\.venv\Lib\site-packages\pandas\core\indexes\base.py", line 3812, in get_loc
    raise KeyError(key) from err
KeyError: 'Объект 1 Угол'

The above exception was the direct cause of the following exception:

Traceback (most recent call last):
  File "c:\python\.venv\Lib\site-packages\sklearn\model_selection\_validation.py", line 866, in _fit_and_score
    estimator.fit(X_train, y_train, **fit_params)
    ~~~~~~~~~~~~~^^^^^^^^^^^^^^^^^^^^^^^^^^^^^^^^
  File "c:\python\.venv\Lib\site-packages\sklearn\base.py", line 1389, in wrapper
    return fit_method(estimator, *args, **kwargs)
  File "c:\python\.venv\Lib\site-packages\sklearn\pipeline.py", line 654, in fit
    Xt = self._fit(X, y, routed_params, raw_params=params)
  File "c:\python\.venv\Lib\site-packages\sklearn\pipeline.py", line 588, in _fit
    X, fitted_transformer = fit_transform_one_cached(
                            ~~~~~~~~~~~~~~~~~~~~~~~~^
        cloned_transformer,
        ^^^^^^^^^^^^^^^^^^^
    ...<5 lines>...
        params=step_params,
        ^^^^^^^^^^^^^^^^^^^
    )
    ^
  File "c:\python\.venv\Lib\site-packages\joblib\memory.py", line 312, in __call__
    return self.func(*args, **kwargs)
           ~~~~~~~~~^^^^^^^^^^^^^^^^^
  File "c:\python\.venv\Lib\site-packages\sklearn\pipeline.py", line 1551, in _fit_transform_one
    res = transformer.fit_transform(X, y, **params.get("fit_transform", {}))
  File "c:\python\.venv\Lib\site-packages\sklearn\utils\_set_output.py", line 319, in wrapped
    data_to_wrap = f(self, X, *args, **kwargs)
  File "c:\python\.venv\Lib\site-packages\sklearn\base.py", line 1389, in wrapper
    return fit_method(estimator, *args, **kwargs)
  File "c:\python\.venv\Lib\site-packages\sklearn\compose\_column_transformer.py", line 993, in fit_transform
    self._validate_column_callables(X)
    ~~~~~~~~~~~~~~~~~~~~~~~~~~~~~~~^^^
  File "c:\python\.venv\Lib\site-packages\sklearn\compose\_column_transformer.py", line 552, in _validate_column_callables
    transformer_to_input_indices[name] = _get_column_indices(X, columns)
                                         ~~~~~~~~~~~~~~~~~~~^^^^^^^^^^^^
  File "c:\python\.venv\Lib\site-packages\sklearn\utils\_indexing.py", line 372, in _get_column_indices
    raise ValueError("A given column is not a column of the dataframe") from e
ValueError: A given column is not a column of the dataframe

2025-05-23 21:58:10,683 - pygad.pygad - ERROR - 
All the 3 fits failed.
It is very likely that your model is misconfigured.
You can try to debug the error by setting error_score='raise'.

Below are more details about the failures:
--------------------------------------------------------------------------------
3 fits failed with the following error:
Traceback (most recent call last):
  File "c:\python\.venv\Lib\site-packages\pandas\core\indexes\base.py", line 3805, in get_loc
    return self._engine.get_loc(casted_key)
           ~~~~~~~~~~~~~~~~~~~~^^^^^^^^^^^^
  File "index.pyx", line 167, in pandas._libs.index.IndexEngine.get_loc
  File "index.pyx", line 196, in pandas._libs.index.IndexEngine.get_loc
  File "pandas\\_libs\\hashtable_class_helper.pxi", line 7081, in pandas._libs.hashtable.PyObjectHashTable.get_item
  File "pandas\\_libs\\hashtable_class_helper.pxi", line 7089, in pandas._libs.hashtable.PyObjectHashTable.get_item
KeyError: 'Объект 1 Угол'

The above exception was the direct cause of the following exception:

Traceback (most recent call last):
  File "c:\python\.venv\Lib\site-packages\sklearn\utils\_indexing.py", line 364, in _get_column_indices
    col_idx = all_columns.get_loc(col)
  File "c:\python\.venv\Lib\site-packages\pandas\core\indexes\base.py", line 3812, in get_loc
    raise KeyError(key) from err
KeyError: 'Объект 1 Угол'

The above exception was the direct cause of the following exception:

Traceback (most recent call last):
  File "c:\python\.venv\Lib\site-packages\sklearn\model_selection\_validation.py", line 866, in _fit_and_score
    estimator.fit(X_train, y_train, **fit_params)
    ~~~~~~~~~~~~~^^^^^^^^^^^^^^^^^^^^^^^^^^^^^^^^
  File "c:\python\.venv\Lib\site-packages\sklearn\base.py", line 1389, in wrapper
    return fit_method(estimator, *args, **kwargs)
  File "c:\python\.venv\Lib\site-packages\sklearn\pipeline.py", line 654, in fit
    Xt = self._fit(X, y, routed_params, raw_params=params)
  File "c:\python\.venv\Lib\site-packages\sklearn\pipeline.py", line 588, in _fit
    X, fitted_transformer = fit_transform_one_cached(
                            ~~~~~~~~~~~~~~~~~~~~~~~~^
        cloned_transformer,
        ^^^^^^^^^^^^^^^^^^^
    ...<5 lines>...
        params=step_params,
        ^^^^^^^^^^^^^^^^^^^
    )
    ^
  File "c:\python\.venv\Lib\site-packages\joblib\memory.py", line 312, in __call__
    return self.func(*args, **kwargs)
           ~~~~~~~~~^^^^^^^^^^^^^^^^^
  File "c:\python\.venv\Lib\site-packages\sklearn\pipeline.py", line 1551, in _fit_transform_one
    res = transformer.fit_transform(X, y, **params.get("fit_transform", {}))
  File "c:\python\.venv\Lib\site-packages\sklearn\utils\_set_output.py", line 319, in wrapped
    data_to_wrap = f(self, X, *args, **kwargs)
  File "c:\python\.venv\Lib\site-packages\sklearn\base.py", line 1389, in wrapper
    return fit_method(estimator, *args, **kwargs)
  File "c:\python\.venv\Lib\site-packages\sklearn\compose\_column_transformer.py", line 993, in fit_transform
    self._validate_column_callables(X)
    ~~~~~~~~~~~~~~~~~~~~~~~~~~~~~~~^^^
  File "c:\python\.venv\Lib\site-packages\sklearn\compose\_column_transformer.py", line 552, in _validate_column_callables
    transformer_to_input_indices[name] = _get_column_indices(X, columns)
                                         ~~~~~~~~~~~~~~~~~~~^^^^^^^^^^^^
  File "c:\python\.venv\Lib\site-packages\sklearn\utils\_indexing.py", line 372, in _get_column_indices
    raise ValueError("A given column is not a column of the dataframe") from e
ValueError: A given column is not a column of the dataframe
Traceback (most recent call last):
  File "c:\python\.venv\Lib\site-packages\pygad\pygad.py", line 1903, in run
    self.last_generation_fitness = self.cal_pop_fitness()
                                   ~~~~~~~~~~~~~~~~~~~~^^
  File "c:\python\.venv\Lib\site-packages\pygad\pygad.py", line 1860, in cal_pop_fitness
    raise ex
  File "c:\python\.venv\Lib\site-packages\pygad\pygad.py", line 1697, in cal_pop_fitness
    fitness = self.fitness_func(self, sol, sol_idx)
  File "C:\Users\IronSmail\AppData\Local\Temp\ipykernel_6008\3357027851.py", line 30, in fitness_rf
    return evaluate(model, X, y)
  File "C:\Users\IronSmail\AppData\Local\Temp\ipykernel_6008\3357027851.py", line 21, in evaluate
    return cross_val_score(pipeline, X, y, cv=3, scoring='accuracy').mean()
           ~~~~~~~~~~~~~~~^^^^^^^^^^^^^^^^^^^^^^^^^^^^^^^^^^^^^^^^^^
  File "c:\python\.venv\Lib\site-packages\sklearn\utils\_param_validation.py", line 216, in wrapper
    return func(*args, **kwargs)
  File "c:\python\.venv\Lib\site-packages\sklearn\model_selection\_validation.py", line 684, in cross_val_score
    cv_results = cross_validate(
        estimator=estimator,
    ...<9 lines>...
        error_score=error_score,
    )
  File "c:\python\.venv\Lib\site-packages\sklearn\utils\_param_validation.py", line 216, in wrapper
    return func(*args, **kwargs)
  File "c:\python\.venv\Lib\site-packages\sklearn\model_selection\_validation.py", line 431, in cross_validate
    _warn_or_raise_about_fit_failures(results, error_score)
    ~~~~~~~~~~~~~~~~~~~~~~~~~~~~~~~~~^^^^^^^^^^^^^^^^^^^^^^
  File "c:\python\.venv\Lib\site-packages\sklearn\model_selection\_validation.py", line 517, in _warn_or_raise_about_fit_failures
    raise ValueError(all_fits_failed_message)
ValueError: 
All the 3 fits failed.
It is very likely that your model is misconfigured.
You can try to debug the error by setting error_score='raise'.

Below are more details about the failures:
--------------------------------------------------------------------------------
3 fits failed with the following error:
Traceback (most recent call last):
  File "c:\python\.venv\Lib\site-packages\pandas\core\indexes\base.py", line 3805, in get_loc
    return self._engine.get_loc(casted_key)
           ~~~~~~~~~~~~~~~~~~~~^^^^^^^^^^^^
  File "index.pyx", line 167, in pandas._libs.index.IndexEngine.get_loc
  File "index.pyx", line 196, in pandas._libs.index.IndexEngine.get_loc
  File "pandas\\_libs\\hashtable_class_helper.pxi", line 7081, in pandas._libs.hashtable.PyObjectHashTable.get_item
  File "pandas\\_libs\\hashtable_class_helper.pxi", line 7089, in pandas._libs.hashtable.PyObjectHashTable.get_item
KeyError: 'Объект 1 Угол'

The above exception was the direct cause of the following exception:

Traceback (most recent call last):
  File "c:\python\.venv\Lib\site-packages\sklearn\utils\_indexing.py", line 364, in _get_column_indices
    col_idx = all_columns.get_loc(col)
  File "c:\python\.venv\Lib\site-packages\pandas\core\indexes\base.py", line 3812, in get_loc
    raise KeyError(key) from err
KeyError: 'Объект 1 Угол'

The above exception was the direct cause of the following exception:

Traceback (most recent call last):
  File "c:\python\.venv\Lib\site-packages\sklearn\model_selection\_validation.py", line 866, in _fit_and_score
    estimator.fit(X_train, y_train, **fit_params)
    ~~~~~~~~~~~~~^^^^^^^^^^^^^^^^^^^^^^^^^^^^^^^^
  File "c:\python\.venv\Lib\site-packages\sklearn\base.py", line 1389, in wrapper
    return fit_method(estimator, *args, **kwargs)
  File "c:\python\.venv\Lib\site-packages\sklearn\pipeline.py", line 654, in fit
    Xt = self._fit(X, y, routed_params, raw_params=params)
  File "c:\python\.venv\Lib\site-packages\sklearn\pipeline.py", line 588, in _fit
    X, fitted_transformer = fit_transform_one_cached(
                            ~~~~~~~~~~~~~~~~~~~~~~~~^
        cloned_transformer,
        ^^^^^^^^^^^^^^^^^^^
    ...<5 lines>...
        params=step_params,
        ^^^^^^^^^^^^^^^^^^^
    )
    ^
  File "c:\python\.venv\Lib\site-packages\joblib\memory.py", line 312, in __call__
    return self.func(*args, **kwargs)
           ~~~~~~~~~^^^^^^^^^^^^^^^^^
  File "c:\python\.venv\Lib\site-packages\sklearn\pipeline.py", line 1551, in _fit_transform_one
    res = transformer.fit_transform(X, y, **params.get("fit_transform", {}))
  File "c:\python\.venv\Lib\site-packages\sklearn\utils\_set_output.py", line 319, in wrapped
    data_to_wrap = f(self, X, *args, **kwargs)
  File "c:\python\.venv\Lib\site-packages\sklearn\base.py", line 1389, in wrapper
    return fit_method(estimator, *args, **kwargs)
  File "c:\python\.venv\Lib\site-packages\sklearn\compose\_column_transformer.py", line 993, in fit_transform
    self._validate_column_callables(X)
    ~~~~~~~~~~~~~~~~~~~~~~~~~~~~~~~^^^
  File "c:\python\.venv\Lib\site-packages\sklearn\compose\_column_transformer.py", line 552, in _validate_column_callables
    transformer_to_input_indices[name] = _get_column_indices(X, columns)
                                         ~~~~~~~~~~~~~~~~~~~^^^^^^^^^^^^
  File "c:\python\.venv\Lib\site-packages\sklearn\utils\_indexing.py", line 372, in _get_column_indices
    raise ValueError("A given column is not a column of the dataframe") from e
ValueError: A given column is not a column of the dataframe

